<?xml version="1.0" encoding="utf-8"?>
<!-- This URDF was automatically created by SolidWorks to URDF Exporter! Originally created by Stephen Brawner (brawner@gmail.com) 
     Commit Version: 1.6.0-4-g7f85cfe  Build Version: 1.6.7995.38578
     For more information, please see http://wiki.ros.org/sw_urdf_exporter -->
<robot
  name="hak_robot">
  <link
    name="base_link">
    <inertial>
      <origin
        xyz="-0.0240911354644466 -5.83268353705106E-05 0.0926994713294401"
        rpy="0 0 0" />
      <mass
        value="9.62014898919541" />
      <inertia
        ixx="0.0575442533822869"
        ixy="3.09831520459753E-06"
        ixz="-0.000101176749175349"
        iyy="0.0789408978568829"
        iyz="-1.92951434916642E-05"
        izz="0.0830868149708986" />
    </inertial>
    <visual>
      <origin
        xyz="0 0 0"
        rpy="0 0 0" />
      <geometry>
        <mesh
          filename="package://hak_robot/meshes/base_link.STL" />
      </geometry>
      <material
        name="">
        <color
          rgba="1 1 1 1" />
      </material>
    </visual>
    <collision>
      <origin
        xyz="0 0 0"
        rpy="0 0 0" />
      <geometry>
        <mesh
          filename="package://hak_robot/meshes/base_link.STL" />
      </geometry>
    </collision>
  </link>
  <link
    name="link1">
    <inertial>
      <origin
        xyz="0.0135514992161213 0.0133449261956699 0.0811768075080785"
        rpy="0 0 0" />
      <mass
        value="4.16238993718028" />
      <inertia
        ixx="0.0316424140253284"
        ixy="-0.00168560732042343"
        ixz="-0.00404622177824349"
        iyy="0.0324038813905126"
        iyz="-0.00843295927887208"
        izz="0.0212652144826027" />
    </inertial>
    <visual>
      <origin
        xyz="0 0 0"
        rpy="0 0 0" />
      <geometry>
        <mesh
          filename="package://hak_robot/meshes/link1.STL" />
      </geometry>
      <material
        name="">
        <color
          rgba="1 1 1 1" />
      </material>
    </visual>
    <collision>
      <origin
        xyz="0 0 0"
        rpy="0 0 0" />
      <geometry>
        <mesh
          filename="package://hak_robot/meshes/link1.STL" />
      </geometry>
    </collision>
  </link>
  <joint
    name="joint1"
    type="revolute">
    <origin
      xyz="0 0 0.184"
      rpy="0 0 0" />
    <parent
      link="base_link" />
    <child
      link="link1" />
    <axis
      xyz="0 0 1" />
    <limit
      lower="-2.697"
      upper="2.697"
      effort="100"
      velocity="5.759" />
  </joint>
  <link
    name="link2">
    <inertial>
      <origin
        xyz="-0.0196245283863793 0.184886439994691 0.0626469399905923"
        rpy="0 0 0" />
      <mass
        value="9.30413334251082" />
      <inertia
        ixx="0.176521085367141"
        ixy="0.00305691275553169"
        ixz="-0.000550101621270848"
        iyy="0.0289143399655914"
        iyz="0.0217589239814347"
        izz="0.178546329293958" />
    </inertial>
    <visual>
      <origin
        xyz="0 0 0"
        rpy="0 0 0" />
      <geometry>
        <mesh
          filename="package://hak_robot/meshes/link2.STL" />
      </geometry>
      <material
        name="">
        <color
          rgba="1 1 1 1" />
      </material>
    </visual>
    <collision>
      <origin
        xyz="0 0 0"
        rpy="0 0 0" />
      <geometry>
        <mesh
          filename="package://hak_robot/meshes/link2.STL" />
      </geometry>
    </collision>
  </link>
  <joint
    name="joint2"
    type="revolute">
    <origin
      xyz="0.040001 0.063 0.169"
      rpy="1.5708 0 0" />
    <parent
      link="link1" />
    <child
      link="link2" />
    <axis
      xyz="0 0 1" />
    <limit
      lower="-2.391"
      upper="1.606"
      effort="100"
      velocity="4.625" />
  </joint>
  <link
    name="link3">
    <inertial>
      <origin
        xyz="0.00945210188615451 0.0100938603855308 0.0614669440841849"
        rpy="0 0 0" />
      <mass
        value="2.77288234473681" />
      <inertia
        ixx="0.00769276898951054"
        ixy="-0.00124378390113676"
        ixz="0.000140303258501715"
        iyy="0.00915324271004037"
        iyz="9.56389680421576E-05"
        izz="0.0101512971449236" />
    </inertial>
    <visual>
      <origin
        xyz="0 0 0"
        rpy="0 0 0" />
      <geometry>
        <mesh
          filename="package://hak_robot/meshes/link3.STL" />
      </geometry>
      <material
        name="">
        <color
          rgba="1 1 1 1" />
      </material>
    </visual>
    <collision>
      <origin
        xyz="0 0 0"
        rpy="0 0 0" />
      <geometry>
        <mesh
          filename="package://hak_robot/meshes/link3.STL" />
      </geometry>
    </collision>
  </link>
  <joint
    name="joint3"
    type="revolute">
    <origin
      xyz="0 0.44001 0.005"
      rpy="0 0 0" />
    <parent
      link="link2" />
    <child
      link="link3" />
    <axis
      xyz="0 0 1" />
    <limit
      lower="-1.309"
      upper="3.665"
      effort="100"
      velocity="6.195" />
  </joint>
  <link
    name="link4">
    <inertial>
      <origin
        xyz="-0.000267685369762405 -1.31817184425867E-05 0.149328083580004"
        rpy="0 0 0" />
      <mass
        value="2.63078855241547" />
      <inertia
        ixx="0.0187988618804413"
        ixy="9.964518494357E-07"
        ixz="8.4029626116062E-06"
        iyy="0.0189997730046198"
        iyz="0.00102096872763372"
        izz="0.00306981351090355" />
    </inertial>
    <visual>
      <origin
        xyz="0 0 0"
        rpy="0 0 0" />
      <geometry>
        <mesh
          filename="package://hak_robot/meshes/link4.STL" />
      </geometry>
      <material
        name="">
        <color
          rgba="1 1 1 1" />
      </material>
    </visual>
    <collision>
      <origin
        xyz="0 0 0"
        rpy="0 0 0" />
      <geometry>
        <mesh
          filename="package://hak_robot/meshes/link4.STL" />
      </geometry>
    </collision>
  </link>
  <joint
    name="joint4"
    type="revolute">
    <origin
      xyz="0.1065 0.032491 0.058"
      rpy="-1.5708 0 -1.5708" />
    <parent
      link="link3" />
    <child
      link="link4" />
    <axis
      xyz="0 0 1" />
    <limit
      lower="-3.491"
      upper="3.491"
      effort="100"
      velocity="7.679" />
  </joint>
  <link
    name="link5">
    <inertial>
      <origin
        xyz="3.65714911787496E-06 0.00574852068385584 -0.0380752001850429"
        rpy="0 0 0" />
      <mass
        value="0.744625128775432" />
      <inertia
        ixx="0.00106633972225257"
        ixy="-9.97399009113836E-09"
        ixz="-2.12723117377069E-08"
        iyy="0.000823697573772714"
        iyz="5.79578062976453E-06"
        izz="0.00100951988524073" />
    </inertial>
    <visual>
      <origin
        xyz="0 0 0"
        rpy="0 0 0" />
      <geometry>
        <mesh
          filename="package://hak_robot/meshes/link5.STL" />
      </geometry>
      <material
        name="">
        <color
          rgba="1 1 1 1" />
      </material>
    </visual>
    <collision>
      <origin
        xyz="0 0 0"
        rpy="0 0 0" />
      <geometry>
        <mesh
          filename="package://hak_robot/meshes/link5.STL" />
      </geometry>
    </collision>
  </link>
  <joint
    name="joint5"
    type="revolute">
    <origin
      xyz="0 -0.039 0.3225"
      rpy="1.5708 0 0" />
    <parent
      link="link4" />
    <child
      link="link5" />
    <axis
      xyz="0 0 1" />
    <limit
      lower="-2.269"
      upper="2.269"
      effort="100"
      velocity="7.854" />
  </joint>
  <link
    name="hkrobot">
    <inertial>
      <origin
        xyz="2.59105466068332E-05 0.00016467152162812 0.00809711053411466"
        rpy="0 0 0" />
      <mass
        value="0.0250254288937889" />
      <inertia
        ixx="6.82453249122362E-06"
        ixy="1.07394209847228E-10"
        ixz="-2.95181073150039E-09"
        iyy="6.93799170565175E-06"
        iyz="-2.10757909903554E-09"
        izz="1.31737499655798E-05" />
    </inertial>
    <visual>
      <origin
        xyz="0 0 0"
        rpy="0 0 0" />
      <geometry>
        <mesh
          filename="package://hak_robot/meshes/hkrobot.STL" />
      </geometry>
      <material
        name="">
        <color
          rgba="1 1 1 1" />
      </material>
    </visual>
    <collision>
      <origin
        xyz="0 0 0"
        rpy="0 0 0" />
      <geometry>
        <mesh
          filename="package://hak_robot/meshes/hkrobot.STL" />
      </geometry>
    </collision>
  </link>
  <joint
    name="j_hkrobot"
    type="revolute">
    <origin
      xyz="0 0.064 -0.039"
      rpy="-1.5708 0 0" />
    <parent
      link="link5" />
    <child
      link="hkrobot" />
    <axis
      xyz="0 0 1" />
    <limit
      lower="-6.28"
      upper="6.28"
      effort="100"
      velocity="12.217" />
  </joint>
</robot>