<?xml version="1.0" encoding="utf-8" ?>
<!-- This URDF was automatically created by SolidWorks to URDF Exporter! Originally created by Stephen Brawner (brawner@gmail.com) 
     Commit Version: 1.6.0-4-g7f85cfe  Build Version: 1.6.7995.38578
     For more information, please see http://wiki.ros.org/sw_urdf_exporter -->
<robot name="hk_robot_gripper">
    <link name="base_link">
        <inertial>
            <origin xyz="-0.0240762155097519 -6.07439183346924E-05 0.0926993711568796" rpy="0 0 0" />
            <mass value="9.61931445064129" />
            <inertia ixx="0.0575442909903654" ixy="3.07705125036709E-06" ixz="-0.000101193617172216" iyy="0.0789407999072904" iyz="-1.92904530466979E-05" izz="0.0830867631685588" />
        </inertial>
        <visual>
            <origin xyz="0 0 0" rpy="0 0 0" />
            <geometry>
                <mesh filename="package://hk_robot_gripper/meshes/base_link.STL" />
            </geometry>
            <material name="">
                <color rgba="1 1 1 1" />
            </material>
        </visual>
        <collision>
            <origin xyz="0 0 0" rpy="0 0 0" />
            <geometry>
                <mesh filename="package://hk_robot_gripper/meshes/base_link.STL" />
            </geometry>
        </collision>
    </link>
    <link name="link1">
        <inertial>
            <origin xyz="0.013501278907053 0.0132999344980556 0.0791632960981127" rpy="0 0 0" />
            <mass value="4.16514672017489" />
            <inertia ixx="0.0316621366802409" ixy="-0.00170242215513643" ixz="-0.00404668810684829" iyy="0.0324133353929007" iyz="-0.00843236952332947" izz="0.0213000779832429" />
        </inertial>
        <visual>
            <origin xyz="0 0 0" rpy="0 0 0" />
            <geometry>
                <mesh filename="package://hk_robot_gripper/meshes/link1.STL" />
            </geometry>
            <material name="">
                <color rgba="1 1 1 1" />
            </material>
        </visual>
        <collision>
            <origin xyz="0 0 0" rpy="0 0 0" />
            <geometry>
                <mesh filename="package://hk_robot_gripper/meshes/link1.STL" />
            </geometry>
        </collision>
    </link>
    <joint name="joint1" type="revolute">
        <origin xyz="0 0 0.186" rpy="0 0 0" />
        <parent link="base_link" />
        <child link="link1" />
        <axis xyz="0 0 1" />
        <limit lower="-2.697" upper="2.697" effort="100" velocity="5.759" />
    </joint>
    <link name="link2">
        <inertial>
            <origin xyz="-0.0196256514811221 -0.0626472193501375 0.184888572229802" rpy="0 0 0" />
            <mass value="9.30405617556521" />
            <inertia ixx="0.176518778248241" ixy="0.000549932280639684" ixz="0.00305551623133291" iyy="0.178546386964241" iyz="-0.0217584604397181" izz="0.0289163608612748" />
        </inertial>
        <visual>
            <origin xyz="0 0 0" rpy="0 0 0" />
            <geometry>
                <mesh filename="package://hk_robot_gripper/meshes/link2.STL" />
            </geometry>
            <material name="">
                <color rgba="1 1 1 1" />
            </material>
        </visual>
        <collision>
            <origin xyz="0 0 0" rpy="0 0 0" />
            <geometry>
                <mesh filename="package://hk_robot_gripper/meshes/link2.STL" />
            </geometry>
        </collision>
    </link>
    <joint name="joint2" type="revolute">
        <origin xyz="0.0400008569999744 0.0630000094679999 0.167000171332406" rpy="0 0 0" />
        <parent link="link1" />
        <child link="link2" />
        <axis xyz="0 -1 0" />
        <limit lower="-2.391" upper="1.606" effort="100" velocity="4.625" />
    </joint>
    <link name="link3">
        <inertial>
            <origin xyz="0.00945000510169165 -0.0614675010251967 0.0100942611493721" rpy="0 0 0" />
            <mass value="2.77294977586238" />
            <inertia ixx="0.00769284832770074" ixy="-0.000140289247145591" ixz="-0.00124387155073294" iyy="0.0101513745832295" iyz="-9.57820241038037E-05" izz="0.00915342052753798" />
        </inertial>
        <visual>
            <origin xyz="0 0 0" rpy="0 0 0" />
            <geometry>
                <mesh filename="package://hk_robot_gripper/meshes/link3.STL" />
            </geometry>
            <material name="">
                <color rgba="1 1 1 1" />
            </material>
        </visual>
        <collision>
            <origin xyz="0 0 0" rpy="0 0 0" />
            <geometry>
                <mesh filename="package://hk_robot_gripper/meshes/link3.STL" />
            </geometry>
        </collision>
    </link>
    <joint name="joint3" type="revolute">
        <origin xyz="0 -0.0050000174826863 0.440008774978337" rpy="0 0 0" />
        <parent link="link2" />
        <child link="link3" />
        <axis xyz="0 1 0" />
        <limit lower="-1.309" upper="3.665" effort="100" velocity="6.195" />
    </joint>
    <link name="link4">
        <inertial>
            <origin xyz="0.150826247882765 4.66255425562883E-06 0.000257245955301189" rpy="0 0 0" />
            <mass value="2.62967639973077" />
            <inertia ixx="0.0030689538134985" ixy="0.00102003831047913" ixz="-7.82342017983218E-06" iyy="0.018999112483095" iyz="-1.4701211861209E-06" izz="0.0187976919727519" />
        </inertial>
        <visual>
            <origin xyz="0 0 0" rpy="0 0 0" />
            <geometry>
                <mesh filename="package://hk_robot_gripper/meshes/link4.STL" />
            </geometry>
            <material name="">
                <color rgba="1 1 1 1" />
            </material>
        </visual>
        <collision>
            <origin xyz="0 0 0" rpy="0 0 0" />
            <geometry>
                <mesh filename="package://hk_robot_gripper/meshes/link4.STL" />
            </geometry>
        </collision>
    </link>
    <joint name="joint4" type="revolute">
        <origin xyz="0.105000707675196 -0.0579999980270505 0.0324910836021022" rpy="0 0 0" />
        <parent link="link3" />
        <child link="link4" />
        <axis xyz="1 0 0" />
        <limit lower="-3.491" upper="3.491" effort="100" velocity="7.679" />
    </joint>
    <link name="link5">
        <inertial>
            <origin xyz="0.00574871866681459 0.0380751786036623 -3.4020706964899E-06" rpy="0 0 0" />
            <mass value="0.744627485770696" />
            <inertia ixx="0.000823713208099127" ixy="-5.78938768950311E-06" ixz="7.00197254616588E-09" iyy="0.00100954176379095" iyz="-2.25097009677508E-08" izz="0.00106632133408634" />
        </inertial>
        <visual>
            <origin xyz="0 0 0" rpy="0 0 0" />
            <geometry>
                <mesh filename="package://hk_robot_gripper/meshes/link5.STL" />
            </geometry>
            <material name="">
                <color rgba="1 1 1 1" />
            </material>
        </visual>
        <collision>
            <origin xyz="0 0 0" rpy="0 0 0" />
            <geometry>
                <mesh filename="package://hk_robot_gripper/meshes/link5.STL" />
            </geometry>
        </collision>
    </link>
    <joint name="joint5" type="revolute">
        <origin xyz="0.32399990421585 -0.0389999939121068 0" rpy="0 0 0" />
        <parent link="link4" />
        <child link="link5" />
        <axis xyz="0 1 0" />
        <limit lower="-2.269" upper="2.269" effort="100" velocity="7.854" />
    </joint>
    <link name="hkrobot">
        <inertial>
            <origin xyz="0.00809711108733446 0.0001646684376791 -2.59085690346161E-05" rpy="0 0 0" />
            <mass value="0.0250254344998689" />
            <inertia ixx="1.31737532314685E-05" ixy="-2.10738247724408E-09" ixz="2.95165208947997E-09" iyy="6.93799359626868E-06" iyz="-1.06818244498264E-10" izz="6.82453394313688E-06" />
        </inertial>
        <visual>
            <origin xyz="0 0 0" rpy="0 0 0" />
            <geometry>
                <mesh filename="package://hk_robot_gripper/meshes/hkrobot.STL" />
            </geometry>
            <material name="">
                <color rgba="1 1 1 1" />
            </material>
        </visual>
        <collision>
            <origin xyz="0 0 0" rpy="0 0 0" />
            <geometry>
                <mesh filename="package://hk_robot_gripper/meshes/hkrobot.STL" />
            </geometry>
        </collision>
    </link>
    <joint name="j_hkrobot" type="revolute">
        <origin xyz="0.064 0.039 0" rpy="0 0 0" />
        <parent link="link5" />
        <child link="hkrobot" />
        <axis xyz="-1 0 0" />
        <limit lower="-6.28" upper="6.28" effort="100" velocity="12.217" />
    </joint>
    <link name="left1">
        <inertial>
            <origin xyz="-0.64524259532042 -0.0383471590972383 -0.409696941227353" rpy="0 0 0" />
            <mass value="29.3496579490047" />
            <inertia ixx="2.58315175853579" ixy="0.000974365436235862" ixz="-0.63100263241913" iyy="2.98278800394886" iyz="0.00682924233693356" izz="0.577700676115089" />
        </inertial>
        <visual>
            <origin xyz="0 0 0" rpy="0 0 0" />
            <geometry>
                <mesh filename="package://hk_robot_gripper/meshes/left1.STL" />
            </geometry>
            <material name="">
                <color rgba="0.647058823529412 0.619607843137255 0.588235294117647 1" />
            </material>
        </visual>
        <collision>
            <origin xyz="0 0 0" rpy="0 0 0" />
            <geometry>
                <mesh filename="package://hk_robot_gripper/meshes/left1.STL" />
            </geometry>
        </collision>
    </link>
    <joint name="joint11" type="revolute">
        <origin xyz="0.15745 0.039894 -0.0038693" rpy="0 0 0" />
        <parent link="hkrobot" />
        <child link="left1" />
        <axis xyz="0 0.026502 -0.99965" />
        <limit lower="0" upper="1" effort="0" velocity="10" />
    </joint>
    <link name="left3">
        <inertial>
            <origin xyz="-0.690224527081833 -0.0409632140203349 -0.417769107510507" rpy="0 0 0" />
            <mass value="29.3496579490047" />
            <inertia ixx="2.58315175853579" ixy="0.000974365436235861" ixz="-0.63100263241913" iyy="2.98278800394886" iyz="0.00682924233693358" izz="0.577700676115089" />
        </inertial>
        <visual>
            <origin xyz="0 0 0" rpy="0 0 0" />
            <geometry>
                <mesh filename="package://hk_robot_gripper/meshes/left3.STL" />
            </geometry>
            <material name="">
                <color rgba="0.647058823529412 0.619607843137255 0.588235294117647 1" />
            </material>
        </visual>
        <collision>
            <origin xyz="0 0 0" rpy="0 0 0" />
            <geometry>
                <mesh filename="package://hk_robot_gripper/meshes/left3.STL" />
            </geometry>
        </collision>
    </link>
    <joint name="joint13" type="revolute">
        <origin xyz="0.044982 0.0026161 0.0080722" rpy="0 0 0" />
        <parent link="left1" />
        <child link="left3" />
        <axis xyz="0 -0.026502 0.99965" />
        <limit lower="-2" upper="2" effort="0" velocity="0" />
    </joint>
    <link name="left2">
        <inertial>
            <origin xyz="-0.66234750333634 -0.026647638457418 -0.409386775736074" rpy="0 0 0" />
            <mass value="29.3496579490047" />
            <inertia ixx="2.58315175853579" ixy="0.000974365436235864" ixz="-0.63100263241913" iyy="2.98278800394886" iyz="0.0068292423369336" izz="0.577700676115089" />
        </inertial>
        <visual>
            <origin xyz="0 0 0" rpy="0 0 0" />
            <geometry>
                <mesh filename="package://hk_robot_gripper/meshes/left2.STL" />
            </geometry>
            <material name="">
                <color rgba="0.647058823529412 0.619607843137255 0.588235294117647 1" />
            </material>
        </visual>
        <collision>
            <origin xyz="0 0 0" rpy="0 0 0" />
            <geometry>
                <mesh filename="package://hk_robot_gripper/meshes/left2.STL" />
            </geometry>
        </collision>
    </link>
    <joint name="joint12" type="revolute">
        <origin xyz="0.17456 0.028194 -0.0041795" rpy="0 0 0" />
        <parent link="hkrobot" />
        <child link="left2" />
        <axis xyz="0 -0.026502 0.99965" />
        <limit lower="-2" upper="1" effort="0" velocity="10" />
    </joint>
    <link name="right1">
        <inertial>
            <origin xyz="-0.640595016600155 0.0355052861104522 -0.407739039153896" rpy="0 0 0" />
            <mass value="29.3496579490047" />
            <inertia ixx="2.58315175853579" ixy="0.000974365436235864" ixz="-0.63100263241913" iyy="2.98278800394886" iyz="0.00682924233693357" izz="0.577700676115089" />
        </inertial>
        <visual>
            <origin xyz="0 0 0" rpy="0 0 0" />
            <geometry>
                <mesh filename="package://hk_robot_gripper/meshes/right1.STL" />
            </geometry>
            <material name="">
                <color rgba="0.647058823529412 0.619607843137255 0.588235294117647 1" />
            </material>
        </visual>
        <collision>
            <origin xyz="0 0 0" rpy="0 0 0" />
            <geometry>
                <mesh filename="package://hk_robot_gripper/meshes/right1.STL" />
            </geometry>
        </collision>
    </link>
    <joint name="joint21" type="revolute">
        <origin xyz="0.1528 -0.033959 -0.0058272" rpy="0 0 0" />
        <parent link="hkrobot" />
        <child link="right1" />
        <axis xyz="0 0.026502 -0.99965" />
        <limit lower="-2" upper="1" effort="0" velocity="1" />
    </joint>
    <link name="right3">
        <inertial>
            <origin xyz="-0.675323419199415 0.0407400486533196 -0.414902826212727" rpy="0 0 0" />
            <mass value="29.3496579490047" />
            <inertia ixx="2.58315175853579" ixy="0.000974365436235861" ixz="-0.63100263241913" iyy="2.98278800394886" iyz="0.00682924233693355" izz="0.577700676115089" />
        </inertial>
        <visual>
            <origin xyz="0 0 0" rpy="0 0 0" />
            <geometry>
                <mesh filename="package://hk_robot_gripper/meshes/right3.STL" />
            </geometry>
            <material name="">
                <color rgba="0.647058823529412 0.619607843137255 0.588235294117647 1" />
            </material>
        </visual>
        <collision>
            <origin xyz="0 0 0" rpy="0 0 0" />
            <geometry>
                <mesh filename="package://hk_robot_gripper/meshes/right3.STL" />
            </geometry>
        </collision>
    </link>
    <joint name="joint23" type="revolute">
        <origin xyz="0.034728 -0.0052348 0.0071638" rpy="0 0 0" />
        <parent link="right1" />
        <child link="right3" />
        <axis xyz="0 0.026502 -0.99965" />
        <limit lower="-2" upper="1" effort="0" velocity="10" />
    </joint>
    <link name="right2">
        <inertial>
            <origin xyz="-0.659874209681463 0.0244211542666706 -0.407332645114089" rpy="0 0 0" />
            <mass value="29.3496579490047" />
            <inertia ixx="2.58315175853579" ixy="0.000974365436235855" ixz="-0.63100263241913" iyy="2.98278800394886" iyz="0.00682924233693357" izz="0.577700676115089" />
        </inertial>
        <visual>
            <origin xyz="0 0 0" rpy="0 0 0" />
            <geometry>
                <mesh filename="package://hk_robot_gripper/meshes/right2.STL" />
            </geometry>
            <material name="">
                <color rgba="0.647058823529412 0.619607843137255 0.588235294117647 1" />
            </material>
        </visual>
        <collision>
            <origin xyz="0 0 0" rpy="0 0 0" />
            <geometry>
                <mesh filename="package://hk_robot_gripper/meshes/right2.STL" />
            </geometry>
        </collision>
    </link>
    <joint name="joint22" type="revolute">
        <origin xyz="0.17208 -0.022875 -0.0062336" rpy="0 0 0" />
        <parent link="hkrobot" />
        <child link="right2" />
        <axis xyz="0 -0.026502 0.99965" />
        <limit lower="-2" upper="1" effort="0" velocity="10" />
    </joint>
    <transmission name="trans_joint1">
        <type>transmission_interface/SimpleTransmission</type>
        <joint name="joint1">
            <hardwareInterface>hardware_interface/EffortJointInterface</hardwareInterface>
        </joint>
        <actuator name="joint1_motor">
            <hardwareInterface>hardware_interface/EffortJointInterface</hardwareInterface>
            <mechanicalReduction>1</mechanicalReduction>
        </actuator>
    </transmission>
    <transmission name="trans_joint2">
        <type>transmission_interface/SimpleTransmission</type>
        <joint name="joint2">
            <hardwareInterface>hardware_interface/EffortJointInterface</hardwareInterface>
        </joint>
        <actuator name="joint2_motor">
            <hardwareInterface>hardware_interface/EffortJointInterface</hardwareInterface>
            <mechanicalReduction>1</mechanicalReduction>
        </actuator>
    </transmission>
    <transmission name="trans_joint3">
        <type>transmission_interface/SimpleTransmission</type>
        <joint name="joint3">
            <hardwareInterface>hardware_interface/EffortJointInterface</hardwareInterface>
        </joint>
        <actuator name="joint3_motor">
            <hardwareInterface>hardware_interface/EffortJointInterface</hardwareInterface>
            <mechanicalReduction>1</mechanicalReduction>
        </actuator>
    </transmission>
    <transmission name="trans_joint4">
        <type>transmission_interface/SimpleTransmission</type>
        <joint name="joint4">
            <hardwareInterface>hardware_interface/EffortJointInterface</hardwareInterface>
        </joint>
        <actuator name="joint4_motor">
            <hardwareInterface>hardware_interface/EffortJointInterface</hardwareInterface>
            <mechanicalReduction>1</mechanicalReduction>
        </actuator>
    </transmission>
    <transmission name="trans_joint5">
        <type>transmission_interface/SimpleTransmission</type>
        <joint name="joint5">
            <hardwareInterface>hardware_interface/EffortJointInterface</hardwareInterface>
        </joint>
        <actuator name="joint5_motor">
            <hardwareInterface>hardware_interface/EffortJointInterface</hardwareInterface>
            <mechanicalReduction>1</mechanicalReduction>
        </actuator>
    </transmission>
    <transmission name="trans_j_hkrobot">
        <type>transmission_interface/SimpleTransmission</type>
        <joint name="j_hkrobot">
            <hardwareInterface>hardware_interface/EffortJointInterface</hardwareInterface>
        </joint>
        <actuator name="j_hkrobot_motor">
            <hardwareInterface>hardware_interface/EffortJointInterface</hardwareInterface>
            <mechanicalReduction>1</mechanicalReduction>
        </actuator>
    </transmission>
    <transmission name="trans_joint11">
        <type>transmission_interface/SimpleTransmission</type>
        <joint name="joint11">
            <hardwareInterface>hardware_interface/EffortJointInterface</hardwareInterface>
        </joint>
        <actuator name="joint11_motor">
            <hardwareInterface>hardware_interface/EffortJointInterface</hardwareInterface>
            <mechanicalReduction>1</mechanicalReduction>
        </actuator>
    </transmission>
    <transmission name="trans_joint13">
        <type>transmission_interface/SimpleTransmission</type>
        <joint name="joint13">
            <hardwareInterface>hardware_interface/EffortJointInterface</hardwareInterface>
        </joint>
        <actuator name="joint13_motor">
            <hardwareInterface>hardware_interface/EffortJointInterface</hardwareInterface>
            <mechanicalReduction>1</mechanicalReduction>
        </actuator>
    </transmission>
    <transmission name="trans_joint12">
        <type>transmission_interface/SimpleTransmission</type>
        <joint name="joint12">
            <hardwareInterface>hardware_interface/EffortJointInterface</hardwareInterface>
        </joint>
        <actuator name="joint12_motor">
            <hardwareInterface>hardware_interface/EffortJointInterface</hardwareInterface>
            <mechanicalReduction>1</mechanicalReduction>
        </actuator>
    </transmission>
    <transmission name="trans_joint21">
        <type>transmission_interface/SimpleTransmission</type>
        <joint name="joint21">
            <hardwareInterface>hardware_interface/EffortJointInterface</hardwareInterface>
        </joint>
        <actuator name="joint21_motor">
            <hardwareInterface>hardware_interface/EffortJointInterface</hardwareInterface>
            <mechanicalReduction>1</mechanicalReduction>
        </actuator>
    </transmission>
    <transmission name="trans_joint23">
        <type>transmission_interface/SimpleTransmission</type>
        <joint name="joint23">
            <hardwareInterface>hardware_interface/EffortJointInterface</hardwareInterface>
        </joint>
        <actuator name="joint23_motor">
            <hardwareInterface>hardware_interface/EffortJointInterface</hardwareInterface>
            <mechanicalReduction>1</mechanicalReduction>
        </actuator>
    </transmission>
    <transmission name="trans_joint22">
        <type>transmission_interface/SimpleTransmission</type>
        <joint name="joint22">
            <hardwareInterface>hardware_interface/EffortJointInterface</hardwareInterface>
        </joint>
        <actuator name="joint22_motor">
            <hardwareInterface>hardware_interface/EffortJointInterface</hardwareInterface>
            <mechanicalReduction>1</mechanicalReduction>
        </actuator>
    </transmission>
    <gazebo>
        <plugin name="gazebo_ros_control" filename="libgazebo_ros_control.so">
            <robotNamespace>/</robotNamespace>
        </plugin>
    </gazebo>
</robot>

